[2022-08-28 11:43:43,781] {processor.py:153} INFO - Started process (PID=11740) to work on /opt/airflow/dags/user_processing1.py
[2022-08-28 11:43:43,782] {processor.py:641} INFO - Processing file /opt/airflow/dags/user_processing1.py for tasks to queue
[2022-08-28 11:43:43,783] {logging_mixin.py:115} INFO - [2022-08-28 11:43:43,783] {dagbag.py:507} INFO - Filling up the DagBag from /opt/airflow/dags/user_processing1.py
[2022-08-28 11:43:43,802] {logging_mixin.py:115} INFO - [2022-08-28 11:43:43,801] {dagbag.py:320} ERROR - Failed to import: /opt/airflow/dags/user_processing1.py
Traceback (most recent call last):
  File "/home/airflow/.local/lib/python3.7/site-packages/airflow/models/dagbag.py", line 317, in parse
    loader.exec_module(new_module)
  File "<frozen importlib._bootstrap_external>", line 728, in exec_module
  File "<frozen importlib._bootstrap>", line 219, in _call_with_frames_removed
  File "/opt/airflow/dags/user_processing1.py", line 19, in <module>
    '''
TypeError: 'module' object is not callable
[2022-08-28 11:43:43,803] {processor.py:653} WARNING - No viable dags retrieved from /opt/airflow/dags/user_processing1.py
[2022-08-28 11:43:43,837] {processor.py:161} INFO - Processing /opt/airflow/dags/user_processing1.py took 0.062 seconds
[2022-08-28 11:44:14,026] {processor.py:153} INFO - Started process (PID=11793) to work on /opt/airflow/dags/user_processing1.py
[2022-08-28 11:44:14,027] {processor.py:641} INFO - Processing file /opt/airflow/dags/user_processing1.py for tasks to queue
[2022-08-28 11:44:14,028] {logging_mixin.py:115} INFO - [2022-08-28 11:44:14,028] {dagbag.py:507} INFO - Filling up the DagBag from /opt/airflow/dags/user_processing1.py
[2022-08-28 11:44:14,042] {logging_mixin.py:115} INFO - [2022-08-28 11:44:14,041] {dagbag.py:320} ERROR - Failed to import: /opt/airflow/dags/user_processing1.py
Traceback (most recent call last):
  File "/home/airflow/.local/lib/python3.7/site-packages/airflow/models/dagbag.py", line 317, in parse
    loader.exec_module(new_module)
  File "<frozen importlib._bootstrap_external>", line 728, in exec_module
  File "<frozen importlib._bootstrap>", line 219, in _call_with_frames_removed
  File "/opt/airflow/dags/user_processing1.py", line 19, in <module>
    '''
TypeError: 'module' object is not callable
[2022-08-28 11:44:14,042] {processor.py:653} WARNING - No viable dags retrieved from /opt/airflow/dags/user_processing1.py
[2022-08-28 11:44:14,071] {processor.py:161} INFO - Processing /opt/airflow/dags/user_processing1.py took 0.050 seconds
[2022-08-28 11:44:44,218] {processor.py:153} INFO - Started process (PID=11855) to work on /opt/airflow/dags/user_processing1.py
[2022-08-28 11:44:44,222] {processor.py:641} INFO - Processing file /opt/airflow/dags/user_processing1.py for tasks to queue
[2022-08-28 11:44:44,223] {logging_mixin.py:115} INFO - [2022-08-28 11:44:44,223] {dagbag.py:507} INFO - Filling up the DagBag from /opt/airflow/dags/user_processing1.py
[2022-08-28 11:44:44,240] {logging_mixin.py:115} INFO - [2022-08-28 11:44:44,239] {dagbag.py:320} ERROR - Failed to import: /opt/airflow/dags/user_processing1.py
Traceback (most recent call last):
  File "/home/airflow/.local/lib/python3.7/site-packages/airflow/models/dagbag.py", line 317, in parse
    loader.exec_module(new_module)
  File "<frozen importlib._bootstrap_external>", line 728, in exec_module
  File "<frozen importlib._bootstrap>", line 219, in _call_with_frames_removed
  File "/opt/airflow/dags/user_processing1.py", line 19, in <module>
    '''
TypeError: 'module' object is not callable
[2022-08-28 11:44:44,241] {processor.py:653} WARNING - No viable dags retrieved from /opt/airflow/dags/user_processing1.py
[2022-08-28 11:44:44,277] {processor.py:161} INFO - Processing /opt/airflow/dags/user_processing1.py took 0.065 seconds
[2022-08-28 11:45:15,036] {processor.py:153} INFO - Started process (PID=11907) to work on /opt/airflow/dags/user_processing1.py
[2022-08-28 11:45:15,037] {processor.py:641} INFO - Processing file /opt/airflow/dags/user_processing1.py for tasks to queue
[2022-08-28 11:45:15,038] {logging_mixin.py:115} INFO - [2022-08-28 11:45:15,038] {dagbag.py:507} INFO - Filling up the DagBag from /opt/airflow/dags/user_processing1.py
[2022-08-28 11:45:15,057] {logging_mixin.py:115} INFO - [2022-08-28 11:45:15,056] {dagbag.py:320} ERROR - Failed to import: /opt/airflow/dags/user_processing1.py
Traceback (most recent call last):
  File "/home/airflow/.local/lib/python3.7/site-packages/airflow/models/dagbag.py", line 317, in parse
    loader.exec_module(new_module)
  File "<frozen importlib._bootstrap_external>", line 728, in exec_module
  File "<frozen importlib._bootstrap>", line 219, in _call_with_frames_removed
  File "/opt/airflow/dags/user_processing1.py", line 19, in <module>
    '''
TypeError: 'module' object is not callable
[2022-08-28 11:45:15,057] {processor.py:653} WARNING - No viable dags retrieved from /opt/airflow/dags/user_processing1.py
[2022-08-28 11:45:15,092] {processor.py:161} INFO - Processing /opt/airflow/dags/user_processing1.py took 0.062 seconds
[2022-08-28 11:45:45,328] {processor.py:153} INFO - Started process (PID=11974) to work on /opt/airflow/dags/user_processing1.py
[2022-08-28 11:45:45,337] {processor.py:641} INFO - Processing file /opt/airflow/dags/user_processing1.py for tasks to queue
[2022-08-28 11:45:45,338] {logging_mixin.py:115} INFO - [2022-08-28 11:45:45,338] {dagbag.py:507} INFO - Filling up the DagBag from /opt/airflow/dags/user_processing1.py
[2022-08-28 11:45:45,354] {logging_mixin.py:115} INFO - [2022-08-28 11:45:45,353] {dagbag.py:320} ERROR - Failed to import: /opt/airflow/dags/user_processing1.py
Traceback (most recent call last):
  File "/home/airflow/.local/lib/python3.7/site-packages/airflow/models/dagbag.py", line 317, in parse
    loader.exec_module(new_module)
  File "<frozen importlib._bootstrap_external>", line 728, in exec_module
  File "<frozen importlib._bootstrap>", line 219, in _call_with_frames_removed
  File "/opt/airflow/dags/user_processing1.py", line 19, in <module>
    '''
TypeError: 'module' object is not callable
[2022-08-28 11:45:45,354] {processor.py:653} WARNING - No viable dags retrieved from /opt/airflow/dags/user_processing1.py
[2022-08-28 11:45:45,385] {processor.py:161} INFO - Processing /opt/airflow/dags/user_processing1.py took 0.062 seconds
[2022-08-28 11:46:15,661] {processor.py:153} INFO - Started process (PID=12027) to work on /opt/airflow/dags/user_processing1.py
[2022-08-28 11:46:15,662] {processor.py:641} INFO - Processing file /opt/airflow/dags/user_processing1.py for tasks to queue
[2022-08-28 11:46:15,663] {logging_mixin.py:115} INFO - [2022-08-28 11:46:15,663] {dagbag.py:507} INFO - Filling up the DagBag from /opt/airflow/dags/user_processing1.py
[2022-08-28 11:46:15,684] {logging_mixin.py:115} INFO - [2022-08-28 11:46:15,683] {dagbag.py:320} ERROR - Failed to import: /opt/airflow/dags/user_processing1.py
Traceback (most recent call last):
  File "/home/airflow/.local/lib/python3.7/site-packages/airflow/models/dagbag.py", line 317, in parse
    loader.exec_module(new_module)
  File "<frozen importlib._bootstrap_external>", line 728, in exec_module
  File "<frozen importlib._bootstrap>", line 219, in _call_with_frames_removed
  File "/opt/airflow/dags/user_processing1.py", line 19, in <module>
    '''
TypeError: 'module' object is not callable
[2022-08-28 11:46:15,685] {processor.py:653} WARNING - No viable dags retrieved from /opt/airflow/dags/user_processing1.py
[2022-08-28 11:46:15,725] {processor.py:161} INFO - Processing /opt/airflow/dags/user_processing1.py took 0.073 seconds
[2022-08-28 11:46:46,578] {processor.py:153} INFO - Started process (PID=12097) to work on /opt/airflow/dags/user_processing1.py
[2022-08-28 11:46:46,599] {processor.py:641} INFO - Processing file /opt/airflow/dags/user_processing1.py for tasks to queue
[2022-08-28 11:46:46,599] {logging_mixin.py:115} INFO - [2022-08-28 11:46:46,599] {dagbag.py:507} INFO - Filling up the DagBag from /opt/airflow/dags/user_processing1.py
[2022-08-28 11:46:46,613] {logging_mixin.py:115} INFO - [2022-08-28 11:46:46,612] {dagbag.py:320} ERROR - Failed to import: /opt/airflow/dags/user_processing1.py
Traceback (most recent call last):
  File "/home/airflow/.local/lib/python3.7/site-packages/airflow/models/dagbag.py", line 317, in parse
    loader.exec_module(new_module)
  File "<frozen importlib._bootstrap_external>", line 728, in exec_module
  File "<frozen importlib._bootstrap>", line 219, in _call_with_frames_removed
  File "/opt/airflow/dags/user_processing1.py", line 19, in <module>
    '''
TypeError: 'module' object is not callable
[2022-08-28 11:46:46,613] {processor.py:653} WARNING - No viable dags retrieved from /opt/airflow/dags/user_processing1.py
[2022-08-28 11:46:46,643] {processor.py:161} INFO - Processing /opt/airflow/dags/user_processing1.py took 0.072 seconds
[2022-08-28 11:47:17,145] {processor.py:153} INFO - Started process (PID=12150) to work on /opt/airflow/dags/user_processing1.py
[2022-08-28 11:47:17,146] {processor.py:641} INFO - Processing file /opt/airflow/dags/user_processing1.py for tasks to queue
[2022-08-28 11:47:17,147] {logging_mixin.py:115} INFO - [2022-08-28 11:47:17,147] {dagbag.py:507} INFO - Filling up the DagBag from /opt/airflow/dags/user_processing1.py
[2022-08-28 11:47:17,166] {logging_mixin.py:115} INFO - [2022-08-28 11:47:17,164] {dagbag.py:320} ERROR - Failed to import: /opt/airflow/dags/user_processing1.py
Traceback (most recent call last):
  File "/home/airflow/.local/lib/python3.7/site-packages/airflow/models/dagbag.py", line 317, in parse
    loader.exec_module(new_module)
  File "<frozen importlib._bootstrap_external>", line 728, in exec_module
  File "<frozen importlib._bootstrap>", line 219, in _call_with_frames_removed
  File "/opt/airflow/dags/user_processing1.py", line 19, in <module>
    '''
TypeError: 'module' object is not callable
[2022-08-28 11:47:17,166] {processor.py:653} WARNING - No viable dags retrieved from /opt/airflow/dags/user_processing1.py
[2022-08-28 11:47:17,219] {processor.py:161} INFO - Processing /opt/airflow/dags/user_processing1.py took 0.087 seconds
[2022-08-28 11:47:48,063] {processor.py:153} INFO - Started process (PID=12212) to work on /opt/airflow/dags/user_processing1.py
[2022-08-28 11:47:48,074] {processor.py:641} INFO - Processing file /opt/airflow/dags/user_processing1.py for tasks to queue
[2022-08-28 11:47:48,075] {logging_mixin.py:115} INFO - [2022-08-28 11:47:48,075] {dagbag.py:507} INFO - Filling up the DagBag from /opt/airflow/dags/user_processing1.py
[2022-08-28 11:47:48,092] {logging_mixin.py:115} INFO - [2022-08-28 11:47:48,091] {dagbag.py:320} ERROR - Failed to import: /opt/airflow/dags/user_processing1.py
Traceback (most recent call last):
  File "/home/airflow/.local/lib/python3.7/site-packages/airflow/models/dagbag.py", line 317, in parse
    loader.exec_module(new_module)
  File "<frozen importlib._bootstrap_external>", line 728, in exec_module
  File "<frozen importlib._bootstrap>", line 219, in _call_with_frames_removed
  File "/opt/airflow/dags/user_processing1.py", line 19, in <module>
    '''
TypeError: 'module' object is not callable
[2022-08-28 11:47:48,093] {processor.py:653} WARNING - No viable dags retrieved from /opt/airflow/dags/user_processing1.py
[2022-08-28 11:47:48,129] {processor.py:161} INFO - Processing /opt/airflow/dags/user_processing1.py took 0.072 seconds
[2022-08-28 11:48:18,239] {processor.py:153} INFO - Started process (PID=12264) to work on /opt/airflow/dags/user_processing1.py
[2022-08-28 11:48:18,240] {processor.py:641} INFO - Processing file /opt/airflow/dags/user_processing1.py for tasks to queue
[2022-08-28 11:48:18,241] {logging_mixin.py:115} INFO - [2022-08-28 11:48:18,241] {dagbag.py:507} INFO - Filling up the DagBag from /opt/airflow/dags/user_processing1.py
[2022-08-28 11:48:18,255] {logging_mixin.py:115} INFO - [2022-08-28 11:48:18,254] {dagbag.py:320} ERROR - Failed to import: /opt/airflow/dags/user_processing1.py
Traceback (most recent call last):
  File "/home/airflow/.local/lib/python3.7/site-packages/airflow/models/dagbag.py", line 317, in parse
    loader.exec_module(new_module)
  File "<frozen importlib._bootstrap_external>", line 728, in exec_module
  File "<frozen importlib._bootstrap>", line 219, in _call_with_frames_removed
  File "/opt/airflow/dags/user_processing1.py", line 19, in <module>
    '''
TypeError: 'module' object is not callable
[2022-08-28 11:48:18,256] {processor.py:653} WARNING - No viable dags retrieved from /opt/airflow/dags/user_processing1.py
[2022-08-28 11:48:18,284] {processor.py:161} INFO - Processing /opt/airflow/dags/user_processing1.py took 0.052 seconds
[2022-08-28 11:48:48,532] {processor.py:153} INFO - Started process (PID=12328) to work on /opt/airflow/dags/user_processing1.py
[2022-08-28 11:48:48,534] {processor.py:641} INFO - Processing file /opt/airflow/dags/user_processing1.py for tasks to queue
[2022-08-28 11:48:48,535] {logging_mixin.py:115} INFO - [2022-08-28 11:48:48,535] {dagbag.py:507} INFO - Filling up the DagBag from /opt/airflow/dags/user_processing1.py
[2022-08-28 11:48:48,552] {logging_mixin.py:115} INFO - [2022-08-28 11:48:48,550] {dagbag.py:320} ERROR - Failed to import: /opt/airflow/dags/user_processing1.py
Traceback (most recent call last):
  File "/home/airflow/.local/lib/python3.7/site-packages/airflow/models/dagbag.py", line 317, in parse
    loader.exec_module(new_module)
  File "<frozen importlib._bootstrap_external>", line 728, in exec_module
  File "<frozen importlib._bootstrap>", line 219, in _call_with_frames_removed
  File "/opt/airflow/dags/user_processing1.py", line 19, in <module>
    '''
TypeError: 'module' object is not callable
[2022-08-28 11:48:48,552] {processor.py:653} WARNING - No viable dags retrieved from /opt/airflow/dags/user_processing1.py
[2022-08-28 11:48:48,596] {processor.py:161} INFO - Processing /opt/airflow/dags/user_processing1.py took 0.071 seconds
[2022-08-28 11:49:18,903] {processor.py:153} INFO - Started process (PID=12381) to work on /opt/airflow/dags/user_processing1.py
[2022-08-28 11:49:18,904] {processor.py:641} INFO - Processing file /opt/airflow/dags/user_processing1.py for tasks to queue
[2022-08-28 11:49:18,911] {logging_mixin.py:115} INFO - [2022-08-28 11:49:18,910] {dagbag.py:507} INFO - Filling up the DagBag from /opt/airflow/dags/user_processing1.py
[2022-08-28 11:49:18,929] {logging_mixin.py:115} INFO - [2022-08-28 11:49:18,928] {dagbag.py:320} ERROR - Failed to import: /opt/airflow/dags/user_processing1.py
Traceback (most recent call last):
  File "/home/airflow/.local/lib/python3.7/site-packages/airflow/models/dagbag.py", line 317, in parse
    loader.exec_module(new_module)
  File "<frozen importlib._bootstrap_external>", line 728, in exec_module
  File "<frozen importlib._bootstrap>", line 219, in _call_with_frames_removed
  File "/opt/airflow/dags/user_processing1.py", line 19, in <module>
    '''
TypeError: 'module' object is not callable
[2022-08-28 11:49:18,930] {processor.py:653} WARNING - No viable dags retrieved from /opt/airflow/dags/user_processing1.py
[2022-08-28 11:49:18,968] {processor.py:161} INFO - Processing /opt/airflow/dags/user_processing1.py took 0.072 seconds
[2022-08-28 11:49:49,046] {processor.py:153} INFO - Started process (PID=12439) to work on /opt/airflow/dags/user_processing1.py
[2022-08-28 11:49:49,047] {processor.py:641} INFO - Processing file /opt/airflow/dags/user_processing1.py for tasks to queue
[2022-08-28 11:49:49,049] {logging_mixin.py:115} INFO - [2022-08-28 11:49:49,049] {dagbag.py:507} INFO - Filling up the DagBag from /opt/airflow/dags/user_processing1.py
[2022-08-28 11:49:49,076] {logging_mixin.py:115} INFO - [2022-08-28 11:49:49,074] {dagbag.py:320} ERROR - Failed to import: /opt/airflow/dags/user_processing1.py
Traceback (most recent call last):
  File "/home/airflow/.local/lib/python3.7/site-packages/airflow/models/dagbag.py", line 317, in parse
    loader.exec_module(new_module)
  File "<frozen importlib._bootstrap_external>", line 728, in exec_module
  File "<frozen importlib._bootstrap>", line 219, in _call_with_frames_removed
  File "/opt/airflow/dags/user_processing1.py", line 19, in <module>
    '''
TypeError: 'module' object is not callable
[2022-08-28 11:49:49,076] {processor.py:653} WARNING - No viable dags retrieved from /opt/airflow/dags/user_processing1.py
[2022-08-28 11:49:49,124] {processor.py:161} INFO - Processing /opt/airflow/dags/user_processing1.py took 0.089 seconds
[2022-08-28 11:50:19,370] {processor.py:153} INFO - Started process (PID=12492) to work on /opt/airflow/dags/user_processing1.py
[2022-08-28 11:50:19,371] {processor.py:641} INFO - Processing file /opt/airflow/dags/user_processing1.py for tasks to queue
[2022-08-28 11:50:19,372] {logging_mixin.py:115} INFO - [2022-08-28 11:50:19,372] {dagbag.py:507} INFO - Filling up the DagBag from /opt/airflow/dags/user_processing1.py
[2022-08-28 11:50:19,391] {logging_mixin.py:115} INFO - [2022-08-28 11:50:19,389] {dagbag.py:320} ERROR - Failed to import: /opt/airflow/dags/user_processing1.py
Traceback (most recent call last):
  File "/home/airflow/.local/lib/python3.7/site-packages/airflow/models/dagbag.py", line 317, in parse
    loader.exec_module(new_module)
  File "<frozen importlib._bootstrap_external>", line 728, in exec_module
  File "<frozen importlib._bootstrap>", line 219, in _call_with_frames_removed
  File "/opt/airflow/dags/user_processing1.py", line 19, in <module>
    '''
TypeError: 'module' object is not callable
[2022-08-28 11:50:19,392] {processor.py:653} WARNING - No viable dags retrieved from /opt/airflow/dags/user_processing1.py
[2022-08-28 11:50:19,426] {processor.py:161} INFO - Processing /opt/airflow/dags/user_processing1.py took 0.063 seconds
[2022-08-28 11:50:49,973] {processor.py:153} INFO - Started process (PID=12550) to work on /opt/airflow/dags/user_processing1.py
[2022-08-28 11:50:49,992] {processor.py:641} INFO - Processing file /opt/airflow/dags/user_processing1.py for tasks to queue
[2022-08-28 11:50:49,994] {logging_mixin.py:115} INFO - [2022-08-28 11:50:49,993] {dagbag.py:507} INFO - Filling up the DagBag from /opt/airflow/dags/user_processing1.py
[2022-08-28 11:50:50,013] {logging_mixin.py:115} INFO - [2022-08-28 11:50:50,011] {dagbag.py:320} ERROR - Failed to import: /opt/airflow/dags/user_processing1.py
Traceback (most recent call last):
  File "/home/airflow/.local/lib/python3.7/site-packages/airflow/models/dagbag.py", line 317, in parse
    loader.exec_module(new_module)
  File "<frozen importlib._bootstrap_external>", line 728, in exec_module
  File "<frozen importlib._bootstrap>", line 219, in _call_with_frames_removed
  File "/opt/airflow/dags/user_processing1.py", line 19, in <module>
    '''
TypeError: 'module' object is not callable
[2022-08-28 11:50:50,014] {processor.py:653} WARNING - No viable dags retrieved from /opt/airflow/dags/user_processing1.py
[2022-08-28 11:50:50,054] {processor.py:161} INFO - Processing /opt/airflow/dags/user_processing1.py took 0.113 seconds
[2022-08-28 11:51:20,136] {processor.py:153} INFO - Started process (PID=12609) to work on /opt/airflow/dags/user_processing1.py
[2022-08-28 11:51:20,136] {processor.py:641} INFO - Processing file /opt/airflow/dags/user_processing1.py for tasks to queue
[2022-08-28 11:51:20,137] {logging_mixin.py:115} INFO - [2022-08-28 11:51:20,137] {dagbag.py:507} INFO - Filling up the DagBag from /opt/airflow/dags/user_processing1.py
[2022-08-28 11:51:20,154] {logging_mixin.py:115} INFO - [2022-08-28 11:51:20,151] {dagbag.py:320} ERROR - Failed to import: /opt/airflow/dags/user_processing1.py
Traceback (most recent call last):
  File "/home/airflow/.local/lib/python3.7/site-packages/airflow/models/dagbag.py", line 317, in parse
    loader.exec_module(new_module)
  File "<frozen importlib._bootstrap_external>", line 728, in exec_module
  File "<frozen importlib._bootstrap>", line 219, in _call_with_frames_removed
  File "/opt/airflow/dags/user_processing1.py", line 19, in <module>
    '''
TypeError: 'module' object is not callable
[2022-08-28 11:51:20,154] {processor.py:653} WARNING - No viable dags retrieved from /opt/airflow/dags/user_processing1.py
[2022-08-28 11:51:20,181] {processor.py:161} INFO - Processing /opt/airflow/dags/user_processing1.py took 0.052 seconds
[2022-08-28 11:51:50,687] {processor.py:153} INFO - Started process (PID=12672) to work on /opt/airflow/dags/user_processing1.py
[2022-08-28 11:51:50,715] {processor.py:641} INFO - Processing file /opt/airflow/dags/user_processing1.py for tasks to queue
[2022-08-28 11:51:50,716] {logging_mixin.py:115} INFO - [2022-08-28 11:51:50,716] {dagbag.py:507} INFO - Filling up the DagBag from /opt/airflow/dags/user_processing1.py
[2022-08-28 11:51:50,731] {logging_mixin.py:115} INFO - [2022-08-28 11:51:50,729] {dagbag.py:320} ERROR - Failed to import: /opt/airflow/dags/user_processing1.py
Traceback (most recent call last):
  File "/home/airflow/.local/lib/python3.7/site-packages/airflow/models/dagbag.py", line 317, in parse
    loader.exec_module(new_module)
  File "<frozen importlib._bootstrap_external>", line 728, in exec_module
  File "<frozen importlib._bootstrap>", line 219, in _call_with_frames_removed
  File "/opt/airflow/dags/user_processing1.py", line 19, in <module>
    '''
TypeError: 'module' object is not callable
[2022-08-28 11:51:50,732] {processor.py:653} WARNING - No viable dags retrieved from /opt/airflow/dags/user_processing1.py
[2022-08-28 11:51:50,759] {processor.py:161} INFO - Processing /opt/airflow/dags/user_processing1.py took 0.079 seconds
[2022-08-28 11:52:21,119] {processor.py:153} INFO - Started process (PID=12733) to work on /opt/airflow/dags/user_processing1.py
[2022-08-28 11:52:21,121] {processor.py:641} INFO - Processing file /opt/airflow/dags/user_processing1.py for tasks to queue
[2022-08-28 11:52:21,121] {logging_mixin.py:115} INFO - [2022-08-28 11:52:21,121] {dagbag.py:507} INFO - Filling up the DagBag from /opt/airflow/dags/user_processing1.py
[2022-08-28 11:52:21,135] {logging_mixin.py:115} INFO - [2022-08-28 11:52:21,133] {dagbag.py:320} ERROR - Failed to import: /opt/airflow/dags/user_processing1.py
Traceback (most recent call last):
  File "/home/airflow/.local/lib/python3.7/site-packages/airflow/models/dagbag.py", line 317, in parse
    loader.exec_module(new_module)
  File "<frozen importlib._bootstrap_external>", line 728, in exec_module
  File "<frozen importlib._bootstrap>", line 219, in _call_with_frames_removed
  File "/opt/airflow/dags/user_processing1.py", line 19, in <module>
    '''
TypeError: 'module' object is not callable
[2022-08-28 11:52:21,135] {processor.py:653} WARNING - No viable dags retrieved from /opt/airflow/dags/user_processing1.py
[2022-08-28 11:52:21,162] {processor.py:161} INFO - Processing /opt/airflow/dags/user_processing1.py took 0.048 seconds
[2022-08-28 11:52:51,466] {processor.py:153} INFO - Started process (PID=12789) to work on /opt/airflow/dags/user_processing1.py
[2022-08-28 11:52:51,467] {processor.py:641} INFO - Processing file /opt/airflow/dags/user_processing1.py for tasks to queue
[2022-08-28 11:52:51,468] {logging_mixin.py:115} INFO - [2022-08-28 11:52:51,468] {dagbag.py:507} INFO - Filling up the DagBag from /opt/airflow/dags/user_processing1.py
[2022-08-28 11:52:51,482] {logging_mixin.py:115} INFO - [2022-08-28 11:52:51,480] {dagbag.py:320} ERROR - Failed to import: /opt/airflow/dags/user_processing1.py
Traceback (most recent call last):
  File "/home/airflow/.local/lib/python3.7/site-packages/airflow/models/dagbag.py", line 317, in parse
    loader.exec_module(new_module)
  File "<frozen importlib._bootstrap_external>", line 728, in exec_module
  File "<frozen importlib._bootstrap>", line 219, in _call_with_frames_removed
  File "/opt/airflow/dags/user_processing1.py", line 19, in <module>
    '''
TypeError: 'module' object is not callable
[2022-08-28 11:52:51,482] {processor.py:653} WARNING - No viable dags retrieved from /opt/airflow/dags/user_processing1.py
[2022-08-28 11:52:51,508] {processor.py:161} INFO - Processing /opt/airflow/dags/user_processing1.py took 0.047 seconds
[2022-08-28 11:53:21,807] {processor.py:153} INFO - Started process (PID=12854) to work on /opt/airflow/dags/user_processing1.py
[2022-08-28 11:53:21,835] {processor.py:641} INFO - Processing file /opt/airflow/dags/user_processing1.py for tasks to queue
[2022-08-28 11:53:21,836] {logging_mixin.py:115} INFO - [2022-08-28 11:53:21,835] {dagbag.py:507} INFO - Filling up the DagBag from /opt/airflow/dags/user_processing1.py
[2022-08-28 11:53:21,849] {logging_mixin.py:115} INFO - [2022-08-28 11:53:21,847] {dagbag.py:320} ERROR - Failed to import: /opt/airflow/dags/user_processing1.py
Traceback (most recent call last):
  File "/home/airflow/.local/lib/python3.7/site-packages/airflow/models/dagbag.py", line 317, in parse
    loader.exec_module(new_module)
  File "<frozen importlib._bootstrap_external>", line 728, in exec_module
  File "<frozen importlib._bootstrap>", line 219, in _call_with_frames_removed
  File "/opt/airflow/dags/user_processing1.py", line 19, in <module>
    '''
TypeError: 'module' object is not callable
[2022-08-28 11:53:21,850] {processor.py:653} WARNING - No viable dags retrieved from /opt/airflow/dags/user_processing1.py
[2022-08-28 11:53:21,876] {processor.py:161} INFO - Processing /opt/airflow/dags/user_processing1.py took 0.074 seconds
[2022-08-28 11:53:52,019] {processor.py:153} INFO - Started process (PID=12914) to work on /opt/airflow/dags/user_processing1.py
[2022-08-28 11:53:52,021] {processor.py:641} INFO - Processing file /opt/airflow/dags/user_processing1.py for tasks to queue
[2022-08-28 11:53:52,022] {logging_mixin.py:115} INFO - [2022-08-28 11:53:52,022] {dagbag.py:507} INFO - Filling up the DagBag from /opt/airflow/dags/user_processing1.py
[2022-08-28 11:53:52,046] {logging_mixin.py:115} INFO - [2022-08-28 11:53:52,044] {dagbag.py:320} ERROR - Failed to import: /opt/airflow/dags/user_processing1.py
Traceback (most recent call last):
  File "/home/airflow/.local/lib/python3.7/site-packages/airflow/models/dagbag.py", line 317, in parse
    loader.exec_module(new_module)
  File "<frozen importlib._bootstrap_external>", line 728, in exec_module
  File "<frozen importlib._bootstrap>", line 219, in _call_with_frames_removed
  File "/opt/airflow/dags/user_processing1.py", line 19, in <module>
    '''
TypeError: 'module' object is not callable
[2022-08-28 11:53:52,047] {processor.py:653} WARNING - No viable dags retrieved from /opt/airflow/dags/user_processing1.py
[2022-08-28 11:53:52,078] {processor.py:161} INFO - Processing /opt/airflow/dags/user_processing1.py took 0.068 seconds
[2022-08-28 11:54:23,002] {processor.py:153} INFO - Started process (PID=12986) to work on /opt/airflow/dags/user_processing1.py
[2022-08-28 11:54:23,020] {processor.py:641} INFO - Processing file /opt/airflow/dags/user_processing1.py for tasks to queue
[2022-08-28 11:54:23,021] {logging_mixin.py:115} INFO - [2022-08-28 11:54:23,021] {dagbag.py:507} INFO - Filling up the DagBag from /opt/airflow/dags/user_processing1.py
[2022-08-28 11:54:23,038] {logging_mixin.py:115} INFO - [2022-08-28 11:54:23,035] {dagbag.py:320} ERROR - Failed to import: /opt/airflow/dags/user_processing1.py
Traceback (most recent call last):
  File "/home/airflow/.local/lib/python3.7/site-packages/airflow/models/dagbag.py", line 317, in parse
    loader.exec_module(new_module)
  File "<frozen importlib._bootstrap_external>", line 728, in exec_module
  File "<frozen importlib._bootstrap>", line 219, in _call_with_frames_removed
  File "/opt/airflow/dags/user_processing1.py", line 19, in <module>
    '''
TypeError: 'module' object is not callable
[2022-08-28 11:54:23,038] {processor.py:653} WARNING - No viable dags retrieved from /opt/airflow/dags/user_processing1.py
[2022-08-28 11:54:23,096] {processor.py:161} INFO - Processing /opt/airflow/dags/user_processing1.py took 0.099 seconds
